try {
    throw RuntimeError("test")
} catch (e) {
    print("caught error")
    x = "success"
}