# Try-catch with exception test
print("Before try")
try {
    print("In try")
    throw RuntimeError("Test error")
    print("After throw")
} catch (error) {
    print("In catch, error:", error)
}
print("After try")